Traceback (most recent call last):
  File "/Users/21ceo/opt/anaconda3/lib/python3.7/site-packages/jupyter_cache/executors/utils.py", line 56, in single_nb_execution
    record_timing=False,
  File "/Users/21ceo/opt/anaconda3/lib/python3.7/site-packages/nbclient/client.py", line 1087, in execute
    return NotebookClient(nb=nb, resources=resources, km=km, **kwargs).execute()
  File "/Users/21ceo/opt/anaconda3/lib/python3.7/site-packages/nbclient/util.py", line 74, in wrapped
    return just_run(coro(*args, **kwargs))
  File "/Users/21ceo/opt/anaconda3/lib/python3.7/site-packages/nbclient/util.py", line 53, in just_run
    return loop.run_until_complete(coro)
  File "/Users/21ceo/opt/anaconda3/lib/python3.7/asyncio/base_events.py", line 587, in run_until_complete
    return future.result()
  File "/Users/21ceo/opt/anaconda3/lib/python3.7/site-packages/nbclient/client.py", line 541, in async_execute
    cell, index, execution_count=self.code_cells_executed + 1
  File "/Users/21ceo/opt/anaconda3/lib/python3.7/site-packages/nbclient/client.py", line 832, in async_execute_cell
    self._check_raise_for_error(cell, exec_reply)
  File "/Users/21ceo/opt/anaconda3/lib/python3.7/site-packages/nbclient/client.py", line 740, in _check_raise_for_error
    raise CellExecutionError.from_cell_and_msg(cell, exec_reply['content'])
nbclient.exceptions.CellExecutionError: An error occurred while executing the following cell:
------------------
# Functions for generating scalar, vector, and matrix
import numpy as np
a = np.array([1,2,3])
print(a)
print(type(a))
print(a.shape)
a[0] = 5
print(a)
print(np.rank(a))
print(a.shape, '\n')

b = np.array([[1,2,3], [4,5,6]])
print(b)
print(type(b))
print(np.rank(b))
print(b.shape)
------------------

[0;31m---------------------------------------------------------------------------[0m
[0;31mAttributeError[0m                            Traceback (most recent call last)
[0;32m<ipython-input-1-6bb0619604fb>[0m in [0;36m<module>[0;34m[0m
[1;32m      7[0m [0ma[0m[0;34m[[0m[0;36m0[0m[0;34m][0m [0;34m=[0m [0;36m5[0m[0;34m[0m[0;34m[0m[0m
[1;32m      8[0m [0mprint[0m[0;34m([0m[0ma[0m[0;34m)[0m[0;34m[0m[0;34m[0m[0m
[0;32m----> 9[0;31m [0mprint[0m[0;34m([0m[0mnp[0m[0;34m.[0m[0mrank[0m[0;34m([0m[0ma[0m[0;34m)[0m[0;34m)[0m[0;34m[0m[0;34m[0m[0m
[0m[1;32m     10[0m [0mprint[0m[0;34m([0m[0ma[0m[0;34m.[0m[0mshape[0m[0;34m,[0m [0;34m'\n'[0m[0;34m)[0m[0;34m[0m[0;34m[0m[0m
[1;32m     11[0m [0;34m[0m[0m

[0;32m~/opt/anaconda3/lib/python3.7/site-packages/numpy/__init__.py[0m in [0;36m__getattr__[0;34m(attr)[0m
[1;32m    218[0m             [0;32melse[0m[0;34m:[0m[0;34m[0m[0;34m[0m[0m
[1;32m    219[0m                 raise AttributeError("module {!r} has no attribute "
[0;32m--> 220[0;31m                                      "{!r}".format(__name__, attr))
[0m[1;32m    221[0m [0;34m[0m[0m
[1;32m    222[0m         [0;32mdef[0m [0m__dir__[0m[0;34m([0m[0;34m)[0m[0;34m:[0m[0;34m[0m[0;34m[0m[0m

[0;31mAttributeError[0m: module 'numpy' has no attribute 'rank'
AttributeError: module 'numpy' has no attribute 'rank'

